Workbook

Sheet Sheet1
A1: service | B1: service_seq | C1: port | D1: direction | E1: geo_id | F1: matched_city | G1: matched_location | H1: matched_alternative | I1: match_status | J1: pair_direction | K1: pair_route_code | L1: pair_service_name | M1: pair_voyage | N1: is_westbound_end
A2: AE1 | B2: 1 | C2: Shanghai | D2: W | E2: 2IW9P6J7XAW72 | F2: Shanghai | G2: CNQSC | H2: CNSGH | I2: matched_exact | J2: W
A3: AE1 | B3: 2 | C3: Yantian | D3: W | E3: 0L3DBFFJ3KZ9A | F3: Yantian | G3: CNYTZ | H3: CNYAT | I3: matched_exact | J3: W
A4: AE1 | B4: 3 | C4: Tanjung Pelepas | D4: W | E4: 2DTLIHUG9YN7S | F4: Tanjung Pelepas | G4: MYTPP | H4: MYTPP | I4: matched_online | J4: W
A5: AE1 | B5: 4 | C5: Rotterdam | D5: W | E5: 1JUKNJGWHQBNJ | F5: Rotterdam | G5: NLRTM | H5: NLROT | I5: matched_online | J5: W
A6: AE1 | B6: 5 | C6: Hamburg | D6: W | E6: 03KFCBH0IX2TA | F6: Hamburg | G6: DEHAM | H6: DEHAM | I6: matched_online | J6: W
A7: AE1 | B7: 6 | C7: Antwerp | D7: W | E7: 0ZBIURQPE236H | F7: Antwerp | G7: BEANR | H7: BEANT | I7: matched_online | J7: E | N7: 1
A8: AE1 | B8: 7 | C8: London Gateway | D8: E | E8: T4HWDGEKCG3L1 | F8: London Gateway | G8: GBLGP | H8: GBLGP | I8: matched_online | J8: E
A9: AE1 | B9: 8 | C9: Port Tangier Mediterranee, Morocco | D9: E | E9: 121VWEKZEDMRJ | F9: Tangier City | G9: MATNG | H9: MATNG | I9: matched_online | J9: E
A10: AE2 | B10: 1 | C10: Ningbo | D10: W | E10: 104T898SJZ6GU | F10: Ningbo | G10: CNZSH | H10: CNNPO | I10: matched_exact
A11: AE2 | B11: 2 | C11: Shanghai | E11: 2IW9P6J7XAW72 | F11: Shanghai | G11: CNQSC | H11: CNSGH | I11: matched_exact
A12: AE2 | B12: 3 | C12: Tanjung Pelepas | E12: 2DTLIHUG9YN7S | F12: Tanjung Pelepas | G12: MYTPP | H12: MYTPP | I12: matched_online
A13: AE2 | B13: 4 | C13: Port Tangier Mediterranee, Morocco | E13: 121VWEKZEDMRJ | F13: Tangier City | G13: MATNG | H13: MATNG | I13: matched_online
A14: AE2 | B14: 6 | C14: Wilhelmshaven | E14: 1ZPUMHQGZ3KOU | F14: Wilhelmshaven | G14: DEWVN | H14: DEWVN | I14: matched_online
A15: AE2 | B15: 7 | C15: Bremerhaven | E15: 3EX4F5S3MB4OU | F15: Bremerhaven | G15: DEBRV | H15: DEBRV | I15: matched_online
A16: AE2 | B16: 8 | C16: Rotterdam | D16: E | E16: 1JUKNJGWHQBNJ | F16: Rotterdam | G16: NLRTM | H16: NLROT | I16: matched_online | J16: E | K16: E3 | L16: AE2 | M16: 609E
A17: AE2 | B17: 9 | C17: Salalah | D17: E | E17: 30ECXPXBQJMHO | F17: Salalah | G17: OMSLL | H17: OMSLV | I17: matched_online
A18: AE3 | B18: 1 | C18: Shanghai | E18: 2IW9P6J7XAW72 | F18: Shanghai | G18: CNQSC | H18: CNSGH | I18: matched_exact
A19: AE3 | B19: 2 | C19: Ningbo | E19: 104T898SJZ6GU | F19: Ningbo | G19: CNZSH | H19: CNNPO | I19: matched_exact
A20: AE3 | B20: 3 | C20: Tanjung Pelepas | D20: W | E20: 2DTLIHUG9YN7S | F20: Tanjung Pelepas | G20: MYTPP | H20: MYTPP | I20: matched_online | J20: W | K20: E2 | L20: AE3 | M20: 610W
A21: AE3 | B21: 4 | C21: Algeciras | D21: N | E21: 05R47F3DBN69Q | F21: Algeciras | G21: ESALG | H21: ESALR | I21: matched_online | J21: N | K21: 3L | L21: AE3 | M21: 605W
A22: AE3 | B22: 5 | C22: London Gateway | D22: N | E22: T4HWDGEKCG3L1 | F22: London Gateway | G22: GBLGP | H22: GBLGP | I22: matched_online
A23: AE3 | B23: 6 | C23: Rotterdam | D23: S | E23: 1JUKNJGWHQBNJ | F23: Rotterdam | G23: NLRTM | H23: NLROT | I23: matched_online | J23: S | K23: 3L | L23: AE3 | M23: 610E
A24: AE3 | B24: 7 | C24: Algeciras | D24: S | E24: 05R47F3DBN69Q | F24: Algeciras | G24: ESALG | H24: ESALR | I24: matched_online
A25: AE5 | B25: 1 | C25: Qingdao | E25: 1YCLYW8V7RZB2 | F25: Qingdao | G25: CNYOK | H25: CNTST | I25: matched_exact
A26: AE5 | B26: 2 | C26: Yantian | E26: 0L3DBFFJ3KZ9A | F26: Yantian | G26: CNYTZ | H26: CNYAT | I26: matched_exact
A27: AE5 | B27: 3 | C27: Tanjung Pelepas | D27: W | E27: 2DTLIHUG9YN7S | F27: Tanjung Pelepas | G27: MYTPP | H27: MYTPP | I27: matched_online | J27: W | K27: E1 | L27: AE5 | M27: 607W
A28: AE5 | B28: 4 | C28: London Gateway | D28: W | E28: T4HWDGEKCG3L1 | F28: London Gateway | G28: GBLGP | H28: GBLGP | I28: matched_online
A29: AE5 | B29: 5 | C29: Hamburg | E29: 03KFCBH0IX2TA | F29: Hamburg | G29: DEHAM | H29: DEHAM | I29: matched_online
A30: AE5 | B30: 6 | C30: Bremerhaven | E30: 3EX4F5S3MB4OU | F30: Bremerhaven | G30: DEBRV | H30: DEBRV | I30: matched_online
A31: AE5 | B31: 7 | C31: Aarhus | E31: 2RX5LS7KU273Y | F31: Aarhus | G31: DKAAR | H31: DKAAR | I31: matched_online
A32: AE5 | B32: 8 | C32: Gothenburg | E32: 148LVMHYNW4N3 | F32: Gothenburg | G32: SEGOT | H32: SEGOT | I32: matched_online
A33: AE5 | B33: 9 | C33: Rotterdam | D33: E | E33: 1JUKNJGWHQBNJ | F33: Rotterdam | G33: NLRTM | H33: NLROT | I33: matched_online | J33: E | K33: E1 | L33: AE5 | M33: 608E
A34: AE5 | B34: 10 | C34: Tanjung Pelepas | D34: E | E34: 2DTLIHUG9YN7S | F34: Tanjung Pelepas | G34: MYTPP | H34: MYTPP | I34: matched_online
A35: AE11 | B35: 1 | C35: Shanghai | E35: 2IW9P6J7XAW72 | F35: Shanghai | G35: CNQSC | H35: CNSGH | I35: matched_exact
A36: AE11 | B36: 2 | C36: Yantian | E36: 0L3DBFFJ3KZ9A | F36: Yantian | G36: CNYTZ | H36: CNYAT | I36: matched_exact
A37: AE11 | B37: 3 | C37: Tanjung Pelepas | E37: 2DTLIHUG9YN7S | F37: Tanjung Pelepas | G37: MYTPP | H37: MYTPP | I37: matched_online
A38: AE11 | B38: 4 | C38: Tangiers (TM2) | E38: 121VWEKZEDMRJ | F38: Tangier City | G38: MATNG | H38: MATNG | I38: matched_online
A39: AE11 | B39: 5 | C39: Valencia | E39: 12LNX9VI6SCYH | F39: Valencia | G39: ESVLC | H39: ESVCI | I39: matched_online
A40: AE11 | B40: 6 | C40: Barcelona | E40: 1FQMCYMU9XLZ2 | F40: Barcelona | G40: ESBCN | H40: ESBCN | I40: matched_online
...

Sheet Sheet2
B1: city | C1: geoid
B2: {=_xlfn.UNIQUE(Sheet1!C2:C59)} -> Shanghai | C2: =_xlfn.XLOOKUP(Sheet2!B2,Sheet1!C2:C59,Sheet1!E2:E59) -> 2IW9P6J7XAW72
B3: Yantian | C3: =_xlfn.XLOOKUP(Sheet2!B3,Sheet1!C3:C60,Sheet1!E3:E60) -> 0L3DBFFJ3KZ9A
B4: Tanjung Pelepas | C4: =_xlfn.XLOOKUP(Sheet2!B4,Sheet1!C4:C61,Sheet1!E4:E61) -> 2DTLIHUG9YN7S
B5: Rotterdam | C5: =_xlfn.XLOOKUP(Sheet2!B5,Sheet1!C5:C62,Sheet1!E5:E62) -> 1JUKNJGWHQBNJ
B6: Hamburg | C6: =_xlfn.XLOOKUP(Sheet2!B6,Sheet1!C6:C63,Sheet1!E6:E63) -> 03KFCBH0IX2TA
B7: Antwerp | C7: =_xlfn.XLOOKUP(Sheet2!B7,Sheet1!C7:C64,Sheet1!E7:E64) -> 0ZBIURQPE236H
B8: London Gateway | C8: =_xlfn.XLOOKUP(Sheet2!B8,Sheet1!C8:C65,Sheet1!E8:E65) -> T4HWDGEKCG3L1
B9: Port Tangier Mediterranee, Morocco | C9: =_xlfn.XLOOKUP(Sheet2!B9,Sheet1!C9:C66,Sheet1!E9:E66) -> 121VWEKZEDMRJ
B10: Ningbo | C10: =_xlfn.XLOOKUP(Sheet2!B10,Sheet1!C10:C67,Sheet1!E10:E67) -> 104T898SJZ6GU
B11: Wilhelmshaven | C11: =_xlfn.XLOOKUP(Sheet2!B11,Sheet1!C11:C68,Sheet1!E11:E68) -> 1ZPUMHQGZ3KOU
B12: Bremerhaven | C12: =_xlfn.XLOOKUP(Sheet2!B12,Sheet1!C12:C69,Sheet1!E12:E69) -> 3EX4F5S3MB4OU
B13: Salalah | C13: =_xlfn.XLOOKUP(Sheet2!B13,Sheet1!C13:C70,Sheet1!E13:E70) -> 30ECXPXBQJMHO
B14: Algeciras | C14: =_xlfn.XLOOKUP(Sheet2!B14,Sheet1!C14:C71,Sheet1!E14:E71) -> 05R47F3DBN69Q
... B30: Istanbul | C30: =_xlfn.XLOOKUP(Sheet2!B30,Sheet1!C30:C87,Sheet1!E30:E87) -> 0FC4MM5Y0O0Z2
B31: Port Tangier | C31: 0C29F4LWXIITO
B32: Vado | C32: 2R3AZ1DW4RJB3
B33: Port Said | C33: Q65JHSTNKPAER

Sheet Sheet3
A1: service | B1: service_seq | C1: port | D1: GeoID
A2: AE1 | B2: 1 | C2: Shanghai | D2: 2IW9P6J7XAW72
A3: AE1 | B3: 2 | C3: Yantian | D3: 0L3DBFFJ3KZ9A
A4: AE1 | B4: 3 | C4: Tanjung Pelepas | D4: 2DTLIHUG9YN7S
A5: AE1 | B5: 4 | C5: Rotterdam | D5: 1JUKNJGWHQBNJ
A6: AE1 | B6: 5 | C6: Hamburg | D6: 03KFCBH0IX2TA
A7: AE1 | B7: 6 | C7: Antwerp | D7: 0ZBIURQPE236H
A8: AE2 | B8: 1 | C8: Ningbo | D8: 104T898SJZ6GU
A9: AE2 | B9: 2 | C9: Shanghai | D9: 2IW9P6J7XAW72
A10: AE2 | B10: 3 | C10: Tanjung Pelepas | D10: 2DTLIHUG9YN7S
A11: AE2 | B11: 4 | C11: Port Tangier | D11: 0C29F4LWXIITO
A12: AE2 | B12: 6 | C12: Wilhelmshaven | D12: 1ZPUMHQGZ3KOU
A13: AE2 | B13: 7 | C13: Bremerhaven | D13: 3EX4F5S3MB4OU
... A46: AE15 | B46: 5 | C46: Port Said | D46: Q65JHSTNKPAER
