Workbook

Sheet PortCalls
A1: service | B1: service_seq | C1: port | D1: GeoID
A2: AE1 | B2: 1 | C2: Shanghai | D2: =_xlfn.XLOOKUP(C2,Sheet1!$A$2:$A$100,Sheet1!$B$2:$B$100) -> 2IW9P6J7XAW72
A3: AE1 | B3: =B2+1 -> 2 | C3: Yantian | D3: =_xlfn.XLOOKUP(C3,Sheet1!$A$2:$A$100,Sheet1!$B$2:$B$100) -> 0L3DBFFJ3KZ9A
A4: AE1 | B4: =B3+1 -> 3 | C4: Tanjung Pelepas | D4: =_xlfn.XLOOKUP(C4,Sheet1!$A$2:$A$100,Sheet1!$B$2:$B$100) -> 2DTLIHUG9YN7S
A5: AE1 | B5: =B4+1 -> 4 | C5: Rotterdam | D5: =_xlfn.XLOOKUP(C5,Sheet1!$A$2:$A$100,Sheet1!$B$2:$B$100) -> 1JUKNJGWHQBNJ
A6: AE1 | B6: =B5+1 -> 5 | C6: Hamburg | D6: =_xlfn.XLOOKUP(C6,Sheet1!$A$2:$A$100,Sheet1!$B$2:$B$100) -> 03KFCBH0IX2TA
A7: AE1 | B7: =B6+1 -> 6 | C7: Antwerp | D7: =_xlfn.XLOOKUP(C7,Sheet1!$A$2:$A$100,Sheet1!$B$2:$B$100) -> 0ZBIURQPE236H
A8: AE1 | B8: =B7+1 -> 7 | C8: London Gateway | D8: =_xlfn.XLOOKUP(C8,Sheet1!$A$2:$A$100,Sheet1!$B$2:$B$100) -> T4HWDGEKCG3L1
A9: AE2 | B9: 1 | C9: Ningbo | D9: =_xlfn.XLOOKUP(C9,Sheet1!$A$2:$A$100,Sheet1!$B$2:$B$100) -> 104T898SJZ6GU
A10: AE2 | B10: =B9+1 -> 2 | C10: Shanghai | D10: =_xlfn.XLOOKUP(C10,Sheet1!$A$2:$A$100,Sheet1!$B$2:$B$100) -> 2IW9P6J7XAW72
A11: AE2 | B11: =B10+1 -> 3 | C11: Tanjung Pelepas | D11: =_xlfn.XLOOKUP(C11,Sheet1!$A$2:$A$100,Sheet1!$B$2:$B$100) -> 2DTLIHUG9YN7S
A12: AE2 | B12: =B11+1 -> 4 | C12: Port Tangier | D12: =_xlfn.XLOOKUP(C12,Sheet1!$A$2:$A$100,Sheet1!$B$2:$B$100) -> 121VWEKZEDMRJ
A13: AE2 | B13: =B12+1 -> 5 | C13: Wilhelmshaven | D13: =_xlfn.XLOOKUP(C13,Sheet1!$A$2:$A$100,Sheet1!$B$2:$B$100) -> 1ZPUMHQGZ3KOU
A14: AE2 | B14: =B13+1 -> 6 | C14: Bremerhaven | D14: =_xlfn.XLOOKUP(C14,Sheet1!$A$2:$A$100,Sheet1!$B$2:$B$100) -> 3EX4F5S3MB4OU
A15: AE3 | B15: 1 | C15: Shanghai | D15: =_xlfn.XLOOKUP(C15,Sheet1!$A$2:$A$100,Sheet1!$B$2:$B$100) -> 2IW9P6J7XAW72
A16: AE3 | B16: =B15+1 -> 2 | C16: Ningbo | D16: =_xlfn.XLOOKUP(C16,Sheet1!$A$2:$A$100,Sheet1!$B$2:$B$100) -> 104T898SJZ6GU
A17: AE3 | B17: =B16+1 -> 3 | C17: Tanjung Pelepas | D17: =_xlfn.XLOOKUP(C17,Sheet1!$A$2:$A$100,Sheet1!$B$2:$B$100) -> 2DTLIHUG9YN7S
A18: AE3 | B18: =B17+1 -> 4 | C18: Algeciras | D18: =_xlfn.XLOOKUP(C18,Sheet1!$A$2:$A$100,Sheet1!$B$2:$B$100) -> 05R47F3DBN69Q
A19: AE3 | B19: =B18+1 -> 5 | C19: London Gateway | D19: =_xlfn.XLOOKUP(C19,Sheet1!$A$2:$A$100,Sheet1!$B$2:$B$100) -> T4HWDGEKCG3L1
A20: AE3 | B20: =B19+1 -> 6 | C20: Rotterdam | D20: =_xlfn.XLOOKUP(C20,Sheet1!$A$2:$A$100,Sheet1!$B$2:$B$100) -> 1JUKNJGWHQBNJ
A21: AE5 | B21: 1 | C21: Qingdao | D21: =_xlfn.XLOOKUP(C21,Sheet1!$A$2:$A$100,Sheet1!$B$2:$B$100) -> 1YCLYW8V7RZB2
A22: AE5 | B22: =B21+1 -> 2 | C22: Yantian | D22: =_xlfn.XLOOKUP(C22,Sheet1!$A$2:$A$100,Sheet1!$B$2:$B$100) -> 0L3DBFFJ3KZ9A
A23: AE5 | B23: =B22+1 -> 3 | C23: Tanjung Pelepas | D23: =_xlfn.XLOOKUP(C23,Sheet1!$A$2:$A$100,Sheet1!$B$2:$B$100) -> 2DTLIHUG9YN7S
A24: AE5 | B24: =B23+1 -> 4 | C24: London Gateway | D24: =_xlfn.XLOOKUP(C24,Sheet1!$A$2:$A$100,Sheet1!$B$2:$B$100) -> T4HWDGEKCG3L1
A25: AE5 | B25: =B24+1 -> 5 | C25: Bremerhaven | D25: =_xlfn.XLOOKUP(C25,Sheet1!$A$2:$A$100,Sheet1!$B$2:$B$100) -> 3EX4F5S3MB4OU
A26: AE5 | B26: =B25+1 -> 6 | C26: Hamburg | D26: =_xlfn.XLOOKUP(C26,Sheet1!$A$2:$A$100,Sheet1!$B$2:$B$100) -> 03KFCBH0IX2TA
A27: AE5 | B27: =B26+1 -> 7 | C27: Rotterdam | D27: =_xlfn.XLOOKUP(C27,Sheet1!$A$2:$A$100,Sheet1!$B$2:$B$100) -> 1JUKNJGWHQBNJ
A28: AE11 | B28: 1 | C28: Shanghai | D28: =_xlfn.XLOOKUP(C28,Sheet1!$A$2:$A$100,Sheet1!$B$2:$B$100) -> 2IW9P6J7XAW72
A29: AE11 | B29: =B28+1 -> 2 | C29: Yantian | D29: =_xlfn.XLOOKUP(C29,Sheet1!$A$2:$A$100,Sheet1!$B$2:$B$100) -> 0L3DBFFJ3KZ9A
A30: AE11 | B30: =B29+1 -> 3 | C30: Tanjung Pelepas | D30: =_xlfn.XLOOKUP(C30,Sheet1!$A$2:$A$100,Sheet1!$B$2:$B$100) -> 2DTLIHUG9YN7S
A31: AE11 | B31: =B30+1 -> 4 | C31: Port Tangier | D31: =_xlfn.XLOOKUP(C31,Sheet1!$A$2:$A$100,Sheet1!$B$2:$B$100) -> 121VWEKZEDMRJ
A32: AE11 | B32: =B31+1 -> 5 | C32: Valencia | D32: =_xlfn.XLOOKUP(C32,Sheet1!$A$2:$A$100,Sheet1!$B$2:$B$100) -> 12LNX9VI6SCYH
A33: AE11 | B33: =B32+1 -> 6 | C33: Barcelona | D33: =_xlfn.XLOOKUP(C33,Sheet1!$A$2:$A$100,Sheet1!$B$2:$B$100) -> 1FQMCYMU9XLZ2
A34: AE11 | B34: =B33+1 -> 7 | C34: La Spezia | D34: =_xlfn.XLOOKUP(C34,Sheet1!$A$2:$A$100,Sheet1!$B$2:$B$100) -> 2743COUCZS8SF
A35: AE11 | B35: =B34+1 -> 8 | C35: Genoa | D35: =_xlfn.XLOOKUP(C35,Sheet1!$A$2:$A$100,Sheet1!$B$2:$B$100) -> 0KSZPEKFXG8ZJ
A36: AE11 | B36: =B35+1 -> 9 | C36: Vado | D36: =_xlfn.XLOOKUP(C36,Sheet1!$A$2:$A$100,Sheet1!$B$2:$B$100) -> 2R3AZ1DW4RJB3
A37: AE12 | B37: 1 | C37: Ningbo | D37: =_xlfn.XLOOKUP(C37,Sheet1!$A$2:$A$100,Sheet1!$B$2:$B$100) -> 104T898SJZ6GU
A38: AE12 | B38: =B37+1 -> 2 | C38: Shanghai | D38: =_xlfn.XLOOKUP(C38,Sheet1!$A$2:$A$100,Sheet1!$B$2:$B$100) -> 2IW9P6J7XAW72
A39: AE12 | B39: =B38+1 -> 3 | C39: Port Said East | D39: =_xlfn.XLOOKUP(C39,Sheet1!$A$2:$A$100,Sheet1!$B$2:$B$100) -> 3I6W2NB2MQV7I
A40: AE12 | B40: =B39+1 -> 4 | C40: Koper | D40: =_xlfn.XLOOKUP(C40,Sheet1!$A$2:$A$100,Sheet1!$B$2:$B$100) -> 2XELE43QKIMIN
...

Sheet Sheet1
A1: city | B1: geoid
A2: Shanghai | B2: 2IW9P6J7XAW72
A3: Yantian | B3: 0L3DBFFJ3KZ9A
A4: Tanjung Pelepas | B4: 2DTLIHUG9YN7S
A5: Rotterdam | B5: 1JUKNJGWHQBNJ
A6: Hamburg | B6: 03KFCBH0IX2TA
A7: Antwerp | B7: 0ZBIURQPE236H
A8: London Gateway | B8: T4HWDGEKCG3L1
A9: Port Tangier | B9: 121VWEKZEDMRJ
A10: Ningbo | B10: 104T898SJZ6GU
A11: Wilhelmshaven | B11: 1ZPUMHQGZ3KOU
A12: Bremerhaven | B12: 3EX4F5S3MB4OU
... A37: Jeddah | B37: 0NJO1NEUBFC7W
